<robot name="swerve_drive">
  <link name="swerve_base_link"/>
  <joint name="swerve_base_joint" type="fixed">
    <parent link="swerve_base_link"/>
    <child link="motor_one"/>
    <origin xyz="0 0 0"/>
  </joint>
  <link name="motor_one">
    <visual>
      <origin rpy="0 3.14159265359 3.14159265359" xyz="0 0 0.018"/>
      <geometry>
        <mesh filename=""/> //need mesh files
      </geometry>
    </visual>
    <collision>
      <origin rpy="0 3.14159265359 3.14159265359" xyz="0 0 0.018"/>
      <geometry>
        <mesh filename=""/>
      </geometry>
    </collision>
  </link>
  <joint name="steer" type="revolute">
    <parent link="motor_one"/>
    <child link="motor_two"/>
    <origin rpy="0 0 0" xyz="0 -0.0003 -0.0435"/>
    <axis xyz="0 0 -1"/>
    <limit effort="300" lower="-1.57" upper="1.57" velocity="0.1"/>
  </joint>
  <link name="motor_two">
    <visual>
      <origin rpy="0 0 0" xyz="0 -0.001 0"/>
      <geometry>
        <mesh filename=""/>
      </geometry>
    </visual>
    <collision>
      <origin rpy="0 0 0" xyz="0 -0.001 0"/>
      <geometry>
        <mesh filename="package://swerve_drive/mesh/motor_two.dae"/>
      </geometry>
    </collision>
  </link>
  <joint name="bracket2drive" type="fixed">
    <parent link="motor_two"/>
    <child link="motor_two_drive"/>
    <origin xyz="0 0 0"/>
    <axis xyz="0 1 0"/>
  </joint>
  <link name="motor_two_drive">
    <visual>
      <origin rpy="1.57079632679 3.14159265359 0" xyz="0 0.018 0.0"/>
      <geometry>
        <mesh filename=""/>
      </geometry>
    </visual>
    <collision>
      <origin rpy="1.57079632679 3.14159265359 0" xyz="0 0.018 0.0"/>
      <geometry>
        <mesh filename=""/>
      </geometry>
    </collision>
  </link>
  <joint name="drive" type="continuous">
    <parent link="motor_two_drive"/>
    <child link="tb3_wheel"/>
    <origin rpy="0 0 0" xyz="0 0 0"/>
    <axis xyz="0 -1 0"/>
  </joint>
  <link name="tb3_wheel">
    <visual>
      <origin rpy="0 0 3.14159265359" xyz="0 -0.01 0"/>
      <geometry>
        <mesh filename=""/>
      </geometry>
    </visual>
    <collision>
      <origin rpy="0 0 3.14159265359" xyz="0 -0.01 0"/>
      <geometry>
        <mesh filename=""/>
      </geometry>
    </collision>
  </link>
</robot>
